Workbook

Sheet Index
A1: THANGAMAYIL JEWELLERY LIMITED
B4: DCF & Comps Analysis
C5: Assumptions
C6: Historical
C7: Model
C8: Ratio Analysis
C9: Scenario
C10: Comps
C11: Comps_data
C12: Market_data
C13: WACC
C14: Beta
C15: Summary

Sheet Assumption
B8: Company Description | C8: THANGAMAYIL JEWELLERY LIMITED
B9: ISIN Code | C9: INE085J01014
B10: Sector Name | C10: CONSUMER DURABLES
B11: Industry | C11: Gems, Jewellery and Watches
B12: Exchange Name | C12: BSE: 533158, NSE: THANGAMAYL
B13: Website | C13: www.thangamayil.com
B14: Company Description | C14: Thangamayil Jewellery Limited (TMJL) is a leading jewellery retailer in South India, positioning itself as a "one-stop shop" for gold, diamond, and silver ornaments. The company serves customers through both physical showrooms and its online platform, offering over 7,000 unique designs. Their product mix ranges from traditional wedding jewellery to bespoke, high-margin diamond and platinum collections. A key differentiator is their early adoption of 100% BIS 916 Hallmarked gold and the use of scientific, tamper-proof quality testing machinery, which pioneered a "quality revolution" in their home market of Madurai.
B15: Current Market Price | C15: =Comps_data!C2 -> 3496.9
B18: Model | C18: The stock is priced for perpetual hyper-growth and offers zero margin of safety. The model assumes structurally capped margins and escalating CapEx/Depreciation to fund South Indian store expansions. Any top-line normalization will trigger violent multiple compression.
C20: Base Case (Implied Value: ~INR 800 - 1,000 | Downside: ~75%) Assumption: Revenue growth fades from 20% to a 4% terminal rate; margins remain flat. Impact: Severe de-rating. As growth cools to industry averages, the market will aggressively compress the 55x multiple to match peers, driving a sharp correction toward intrinsic value.
C22: Bull Case (Implied Value: Mild Premium to Base | Downside: Significant) Assumption: Flawless execution with peak 25% near-term growth and an elevated 4.5% terminal rate. Impact: Even under mathematically perfect conditions, the DCF cannot bridge the gap to the current market price. The stock is already priced beyond perfection.
C24: Bear Case (Implied Value: Sub-INR 700 | Downside: Catastrophic) Assumption: Growth stunts early (12%) due to macro headwinds or competitor cannibalization. Impact: Slower revenue fails to absorb the heavy fixed CapEx of the new store rollout. The fixed-cost drag crushes already-thin margins, prompting a brutal sell-off.
B26: Scenario | C26: Base Case Revenue Growth (FY26: 20% → FY30: 9% → Terminal: 4%) Near-term growth is strictly anchored to management's FY25 official guidance to "nearly double the top line in the next four years," which mathematically requires an ~18.9% CAGR. The model projects an initial 20.0% growth rate to capture the immediate upside of the new Chennai flagship operations. However, to ensure macroeconomic realism, this hyper-growth phase is modeled to taper down smoothly over the forecast period, converging precisely with the 9.0% industry average by FY30 (as projected by the IBEF 2030 Gems & Jewellery market forecast). Terminal growth ultimately settles at 4.0%, in line with long-term RBI inflation targets.
C28: Bull Case Revenue Growth (FY26: 25% → FY30: 11% → Terminal: 4.5%) Near-term growth assumes the company successfully sustains its historical outperformance, anchored strictly to the 25.0% 5-year retail revenue CAGR reported in the FY25 Annual Report. This models flawless execution of the Tier-1 Chennai flagship rollout and aggressive customer acquisition via the high-yielding "Digi Gold" scheme (which management notes drives up to 185% redemption values). Over the medium term, growth tapers but structurally bottoms out at 11.0% by FY30—commanding a consistent +200 bps premium over the 9.0% IBEF industry average. This trajectory reflects sustained, aggressive market share capture from the unorganized sector. Terminal growth is modeled at a slightly elevated 4.5% to reflect a permanently strengthened market position.
C30: Bear Case Revenue Growth (FY26: 12% → FY30: 7% → Terminal: 4.0%) Near-term growth models a severe structural deceleration, completely bypassing management's optimistic targets and dropping immediately to 12.0% (the baseline near-term growth projection for the broader Indian retail jewellery segment). This assumes an immediate consumer demand shock, highly volatile gold pricing, or a failure of the newly funded store expansions to gain regional traction. By FY30, growth further deteriorates to 7.0%, representing a strict -200 bps discount to the 9.0% IBEF industry average. This trajectory mathematically prices in heavy market share cannibalization from larger national competitors (e.g., Kalyan, Tanishq) and an inability to generate sufficient top-line velocity to absorb the fixed CapEx load. Terminal growth settles at the standard 4.0% inflation proxy.
B32: Comps | C32: The company is trading at a significant premium to peers, with EV/Sales (1.9x vs ~1.0x), EV/EBITDA (34.7x vs ~16.0x), and P/E (55.1x vs ~20.7x). This clearly indicates market expectations of superior growth and profitability. However, the implied valuation from comps suggests a fair value range of ~₹1,310–₹1,569 per share, which is substantially lower than the current market price of ₹3,497, indicating potential overvaluation. The premium valuation is likely driven by strong growth visibility, regional dominance, and improving operational efficiency, but the extent of the premium appears stretched relative to peers. Unless the company significantly outperforms peer growth and margins, the current valuation may not be sustainable, implying downside risk based on relative valuation.
B34: WACC | C34: The company has a low leverage profile with ~28.1% debt and 71.9% equity, indicating a conservative capital structure. The cost of debt is relatively low at ~5.8% (post-tax), reflecting manageable borrowing costs, while the cost of equity stands at ~10.8%, driven by moderate market risk assumptions. The levered beta (~0.45–0.49) is significantly lower than peers, suggesting lower perceived volatility and risk. Overall, the WACC of ~9.4% is reasonable and on the lower side, implying a lower discount rate and higher valuation sensitivity in the DCF. The company’s low beta and conservative leverage reduce its overall cost of capital, supporting higher valuations, but this also means that any change in growth or risk assumptions will have a significant impact on valuation outcomes.
B36: Valuation Summary | C36: The Comps-based valuation range (₹1,310–₹1,569) and DCF valuation range (₹773–₹975) are both significantly below the current market price (~₹3,497), indicating a material overvaluation based on intrinsic and relative methods. The market consensus range (₹1,200–₹1,600) is broadly aligned with comps, reinforcing a fair value band well below the current trading level. The 52-week high (~₹3,497) is close to the current price, suggesting the stock is trading near peak levels without fundamental support from valuation models. The wide gap between market price and valuation outputs indicates that the stock is being priced on aggressive growth expectations rather than current fundamentals. The stock appears significantly overvalued across all valuation approaches, implying limited upside and meaningful downside risk unless the company delivers exceptionally strong growth beyond current projections.

Sheet Historical
A1: THANGAMAYIL JEWELLERY LIMITED
A2: HISTORICAL FINANCIAL INFORMATION
L3: INR in Lakh
A4: INCOME STATEMENT | H4: 2021 | I4: =H4+1 -> 2022 | J4: =I4+1 -> 2023 | K4: =J4+1 -> 2024 | L4: =K4+1 -> 2025
D5: I. Revenue from operations | H5: 181862 | I5: 219308 | J5: 315255 | K5: 382678 | L5: 491058
D6: II. Other income | H6: 232.14 | I6: 167 | J6: 335 | K6: 541 | L6: 572
D7: III. Total income (I+II) | H7: =SUM(H5:H6) -> 182094.14 | I7: =SUM(I5:I6) -> 219475 | J7: =SUM(J5:J6) -> 315590 | K7: =SUM(K5:K6) -> 383219 | L7: =SUM(L5:L6) -> 491630
D8: IV. Expenses: | H8: - | I8: - | J8: - | K8: - | L8: - | R8: 1
D9: Cost of materials consumed | H9: 163048 | I9: 195294 | J9: 273003 | K9: 344801 | L9: 493209
D10: Purchases of stock-in-trade | H10: 5409.57 | I10: 12870 | J10: 30265 | K10: 19158 | L10: 27207
D11: Changes in inventories of finished goods, work-in-progress and stock-in-trade | H11: -9176.91 | I11: -10672 | J11: -21627 | K11: -21978 | L11: -79148
D12: Manufacturing Expenses | H12: 1865.12 | I12: 2046 | J12: 3891 | K12: 5403 | L12: 6749
D13: Employee benefits expenses | H13: 3328.13 | I13: 4513 | J13: 5842 | K13: 6818 | L13: 9340
D14: Finance costs | H14: 2290.57 | I14: 2618 | J14: 3492 | K14: 3633 | L14: 4107
D15: Depreciation and amortization expenses | H15: 946.99 | I15: 965 | J15: 1339 | K15: 1636 | L15: 2369
D16: Other expenses | H16: 2685.74 | I16: 6638 | J16: 8591 | K16: 7239 | L16: 11805
D17: Total expenses | H17: =SUM(H9:H16) -> 170397.21 | I17: =SUM(I9:I16) -> 214272 | J17: =SUM(J9:J16) -> 304796 | K17: =SUM(K9:K16) -> 366710 | L17: =SUM(L9:L16) -> 475638
D18: V. Profit before tax (III-IV) | H18: =H7-H17 -> 11696.93 | I18: =I7-I17 -> 5203 | J18: =J7-J17 -> 10794 | K18: =K7-K17 -> 16509 | L18: =L7-L17 -> 15992
D19: VI. Tax expenses | H19: - | I19: - | J19: - | K19: - | L19: -
D20: • Current Tax | H20: 3026.75 | I20: 1379 | J20: 2864 | K20: 4207 | L20: 4175
D21: • Adjustment of tax relating to earlier periods | H21: 38.28 | I21: - | J21: 79 | K21: - | L21: 69
D22: • Deferred Tax | H22: -26.3 | I22: -31 | J22: -123 | K22: -23 | L22: -122
D23: Total Tax Expenses | H23: =SUM(H20:H22) -> 3038.73 | I23: =SUM(I20:I22) -> 1348 | J23: =SUM(J20:J22) -> 2820 | K23: =SUM(K20:K22) -> 4184 | L23: =SUM(L20:L22) -> 4122
D24: VII. Profit for the year ( V-VI) | H24: =H18-H23 -> 8658.2 | I24: =I18-I23 -> 3855 | J24: =J18-J23 -> 7974 | K24: =K18-K23 -> 12325 | L24: =L18-L23 -> 11870
D25: VIII. Other comprehensive income
A27: BALANCE SHEET | H27: 2021 | I27: =H27+1 -> 2022 | J27: =I27+1 -> 2023 | K27: =J27+1 -> 2024 | L27: =K27+1 -> 2025
C28: ASSETS
D29: Non-current assets
D30: a. Property, Plant and Equipment | H30: 6860.97 | I30: 7290 | J30: 9902 | K30: 12265 | L30: 15369
D31: b. Capital work- in-progress | H31: 227.96 | I31: 684 | J31: 160 | K31: 236 | L31: 1127
D32: c. Intangible assets | H32: 74.45 | I32: 85 | J32: 98 | K32: 160 | L32: 166
D33: d. Right-of - Use Assets | H33: 943.63 | I33: 1069 | J33: 2013 | K33: 2928 | L33: 4526
D34: e. Financial assets | H34: - | I34: - | J34: - | K34: - | L34: -
D35: i. Other financial assets(non-current) | H35: 38.6 | I35: 41 | J35: 37 | K35: 40 | L35: 43
D36: f. Deferred Tax Assets (net) | H36: 85.05 | I36: 111 | J36: 238 | K36: 250 | L36: 400
D37: g. Other non-current assets | H37: 1034.66 | I37: 1311 | J37: 1221 | K37: 1468 | L37: 2163
D38: Total Non-Current Assests | H38: =SUM(H30:H37) -> 9265.32 | I38: =SUM(I30:I37) -> 10591 | J38: =SUM(J30:J37) -> 13669 | K38: =SUM(K30:K37) -> 17347 | L38: =SUM(L30:L37) -> 23794
D39: Current assets | H39: - | I39: - | J39: - | K39: - | L39: -
D40: a. Inventories | H40: 64923.02 | I40: 75002 | J40: 98234 | K40: 118923 | L40: 197857
D41: b. Financial assets | H41: - | I41: - | J41: - | K41: - | L41: -
...

Sheet Model
A1: =Historical!A1 -> THANGAMAYIL JEWELLERY LIMITED | H1: Historical Period | M1: Forecasted Period
A2: Financial Statements & DCF Analysis | H2: =Historical!H4 -> 2021 | I2: =Historical!I4 -> 2022 | J2: =Historical!J4 -> 2023 | K2: =Historical!K4 -> 2024 | L2: =Historical!L4 -> 2025 | M2: =L2+1 -> 2026 | N2: =M2+1 -> 2027 | O2: =N2+1 -> 2028 | P2: =O2+1 -> 2029 | Q2: =P2+1 -> 2030 | R2: =Q2+1 -> 2031 | S2: =R2+1 -> 2032 | T2: =S2+1 -> 2033 | ... V2: =U2+1 -> 2035
D3: Master Check | H3: =IF(ABS(H73)>1, "error", "Ok") -> Ok | I3: =IF(ABS(I73)>1, "error", "Ok") -> Ok | J3: =IF(ABS(J73)>1, "error", "Ok") -> Ok | K3: =IF(ABS(K73)>1, "error", "Ok") -> Ok | L3: =IF(ABS(L73)>1, "error", "Ok") -> Ok | M3: =IF(ABS(M73)>1, "error", "Ok") -> Ok | N3: =IF(ABS(N73)>1, "error", "Ok") -> Ok | O3: =IF(ABS(O73)>1, "error", "Ok") -> Ok | ... V3: =IF(ABS(V73)>1, "error", "Ok") -> Ok
V4: INR in Lakh
A5: Ratios
D7: LIVE SCENARIO | E7: Bear Case | F7: Units | G7: =IF(E7=Scenario!D5,1,IF(Model!E7=Scenario!D6,2,3)) -> 3
D8: Revenue Growth | F8: % | H8: - | I8: =I$25/H$25-1 -> 0.20590338 | J8: =J$25/I$25-1 -> 0.43749886 | K8: =K$25/J$25-1 -> 0.21386814 | L8: =L$25/K$25-1 -> 0.28321461 | M8: =(M25/L25)-1 -> 0.56328753 | N8: {=CHOOSE($G$7,Scenario!$I$5:$Q$5,Scenario!$I$6:$Q$6,Scenario!$I$7:$Q$7)} -> 0.105 | O8: 0.09 | P8: 0.08 | Q8: 0.07 | R8: 0.06 | S8: 0.055 | T8: 0.05 | U8: 0.045 | V8: 0.04
D9: Cost of Goods Sold(% of Revenue) | F9: % | H9: =-H$26/H$25 -> 0.88608824 | I9: =-I$26/I$25 -> 0.90985281 | J9: =-J$26/J$25 -> 0.90571759 | K9: =-K$26/K$25 -> 0.90777102 | L9: =-L$26/L$25 -> 0.91235048 | M9: =AVERAGE($H9:$L9) -> 0.90435603 | N9: =AVERAGE($H9:$L9) -> 0.90435603 | O9: =AVERAGE($H9:$L9) -> 0.90435603 | P9: =AVERAGE($H9:$L9) -> 0.90435603 | Q9: =AVERAGE($H9:$L9) -> 0.90435603 | R9: =AVERAGE($H9:$L9) -> 0.90435603 | S9: =AVERAGE($H9:$L9) -> 0.90435603 | T9: =AVERAGE($H9:$L9) -> 0.90435603 | ... V9: =AVERAGE($H9:$L9) -> 0.90435603
D10: Salaries and Benefits(% of Revenue) | F10: % | H10: =-H$29/H$25 -> 0.018300305 | I10: =-I$29/I$25 -> 0.020578365 | J10: =-J$29/J$25 -> 0.01853103 | K10: =-K$29/K$25 -> 0.017816546 | L10: =-L$29/L$25 -> 0.019020156 | M10: =AVERAGE($H10:$L10) -> 0.01884928 | N10: =AVERAGE($H10:$L10) -> 0.01884928 | O10: =AVERAGE($H10:$L10) -> 0.01884928 | P10: =AVERAGE($H10:$L10) -> 0.01884928 | Q10: =AVERAGE($H10:$L10) -> 0.01884928 | R10: =AVERAGE($H10:$L10) -> 0.01884928 | S10: =AVERAGE($H10:$L10) -> 0.01884928 | T10: =AVERAGE($H10:$L10) -> 0.01884928 | ... V10: =AVERAGE($H10:$L10) -> 0.01884928
D11: Other SG&A Expenses(% of Revenue) | F11: % | H11: =-H$30/H$25 -> 0.014768011 | I11: =-I$30/I$25 -> 0.030267934 | J11: =-J$30/J$25 -> 0.027250956 | K11: =-K$30/K$25 -> 0.018916687 | L11: =-L$30/L$25 -> 0.02403993 | M11: =AVERAGE($H11:$L11) -> 0.023048703 | N11: =AVERAGE($H11:$L11) -> 0.023048703 | O11: =AVERAGE($H11:$L11) -> 0.023048703 | P11: =AVERAGE($H11:$L11) -> 0.023048703 | Q11: =AVERAGE($H11:$L11) -> 0.023048703 | R11: =AVERAGE($H11:$L11) -> 0.023048703 | S11: =AVERAGE($H11:$L11) -> 0.023048703 | T11: =AVERAGE($H11:$L11) -> 0.023048703 | ... V11: =AVERAGE($H11:$L11) -> 0.023048703
D12: Depriciation & Amortization Expenses (% of PP&E) | F12: % | H12: - | I12: =-I$32/I$115 -> 0.11903279 | J12: =-J$32/J$115 -> 0.1466915 | K12: =-K$32/K$115 -> 0.13439579 | L12: =-L$32/L$115 -> 0.15196613 | M12: =I12 + IF(MOD(COLUMN(J12)-COLUMN($I$12), 3)=1, 0.02, 0) -> 0.13903279 | N12: =I12 + IF(MOD(COLUMN(J12)-COLUMN($I$12), 3)=1, 0.02, 0) -> 0.13903279 | O12: =I12 + IF(MOD(COLUMN(J12)-COLUMN($I$12), 3)=1, 0.02, 0) -> 0.13903279 | P12: =L12 + IF(MOD(COLUMN(M12)-COLUMN($I$12), 3)=1, 0.02, 0) -> 0.17196613 | Q12: =L12 + IF(MOD(COLUMN(M12)-COLUMN($I$12), 3)=1, 0.02, 0) -> 0.17196613 | R12: =L12 + IF(MOD(COLUMN(M12)-COLUMN($I$12), 3)=1, 0.02, 0) -> 0.17196613 | S12: =O12 + IF(MOD(COLUMN(P12)-COLUMN($I$12), 3)=1, 0.02, 0) -> 0.15903279 | T12: =O12 + IF(MOD(COLUMN(P12)-COLUMN($I$12), 3)=1, 0.02, 0) -> 0.15903279 | U12: =O12 + IF(MOD(COLUMN(P12)-COLUMN($I$12), 3)=1, 0.02, 0) -> 0.15903279 | V12: =R12 + IF(MOD(COLUMN(S12)-COLUMN($I$12), 3)=1, 0.02, 0) -> 0.19196613
D13: Interest (% of Debt) | F13: % | H13: - | I13: =-I$34/I$121 -> 0.093397196 | J13: =-J$34/J$121 -> 0.083178505 | K13: =-K$34/K$121 -> 0.063628562 | L13: =-L$34/L$121 -> 0.077210859 | M13: =L13 -> 0.077210859 | N13: =M13 -> 0.077210859 | O13: =N13 -> 0.077210859 | P13: =O13 -> 0.077210859 | Q13: =P13 -> 0.077210859 | R13: =Q13 -> 0.077210859 | S13: =R13 -> 0.077210859 | T13: =S13 -> 0.077210859 | ... V13: =U13 -> 0.077210859
D14: Other Income (Expenses) (% of Revenue) | F14: % | H14: =H$35/H$25 -> 0.0012764624 | I14: =I$35/I$25 -> 0.00076148613 | J14: =J$35/J$25 -> 0.0010626318 | K14: =K$35/K$25 -> 0.0014137212 | L14: =L$35/L$25 -> 0.0011648319 | M14: =AVERAGE($H14:$L14) -> 0.0011358267 | N14: =AVERAGE($H14:$L14) -> 0.0011358267 | O14: =AVERAGE($H14:$L14) -> 0.0011358267 | P14: =AVERAGE($H14:$L14) -> 0.0011358267 | Q14: =AVERAGE($H14:$L14) -> 0.0011358267 | R14: =AVERAGE($H14:$L14) -> 0.0011358267 | S14: =AVERAGE($H14:$L14) -> 0.0011358267 | T14: =AVERAGE($H14:$L14) -> 0.0011358267 | ... V14: =AVERAGE($H14:$L14) -> 0.0011358267
D15: Tax Rate (% of Earnings before tax) | F15: % | H15: =-H$37/H$36 -> 0.25978868 | I15: =-I$37/I$36 -> 0.2590813 | J15: =-J$37/J$36 -> 0.26125625 | K15: =-K$37/K$36 -> 0.25343752 | L15: =-L$37/L$36 -> 0.25775388 | M15: =AVERAGE($H15:$L15) -> 0.25826353 | N15: =AVERAGE($H15:$L15) -> 0.25826353 | O15: =MIN((M15)+0.5%,30%) -> 0.26326353 | P15: =MIN((N15)+0.5%,30%) -> 0.26326353 | Q15: =MIN((O15)+0.5%,30%) -> 0.26826353 | R15: =MIN((P15)+0.5%,30%) -> 0.26826353 | S15: =MIN((Q15)+0.5%,30%) -> 0.27326353 | T15: =MIN((R15)+0.5%,30%) -> 0.27326353 | U15: =MIN((S15)+0.5%,30%) -> 0.27826353 | V15: =MIN((T15)+0.5%,30%) -> 0.27826353
D16: Dividends Payout | F16: % | H16: =-H$96/H$38 -> 0.095074034 | I16: =-I$96/I$38 -> 0.32036316 | J16: =-J$96/J$38 -> 0.18924003 | K16: =-K$96/K$38 -> 0.15586207 | L16: =-L$96/L$38 -> 0.13866891 | M16: =AVERAGE($H16:$L16) -> 0.17984164 | N16: =AVERAGE($H16:$L16) -> 0.17984164 | O16: =AVERAGE($H16:$L16) -> 0.17984164 | P16: =AVERAGE($H16:$L16) -> 0.17984164 | Q16: =AVERAGE($H16:$L16) -> 0.17984164 | R16: =AVERAGE($H16:$L16) -> 0.17984164 | S16: =AVERAGE($H16:$L16) -> 0.17984164 | T16: =AVERAGE($H16:$L16) -> 0.17984164 | ... V16: =AVERAGE($H16:$L16) -> 0.17984164
D17: Accounts Receivable | F17: Days | H17: =H47/H25*365 -> 0.51867322 | I17: =I47/I25*365 -> 0.4360534 | J17: =J47/J25*365 -> 0.36702035 | K17: =K47/K25*365 -> 0.40632072 | L17: =L47/L25*365 -> 0.63923203 | M17: =AVERAGE($H17:$L17) -> 0.47345994 | N17: =AVERAGE($H17:$L17) -> 0.47345994 | O17: =AVERAGE($H17:$L17) -> 0.47345994 | P17: =AVERAGE($H17:$L17) -> 0.47345994 | Q17: =AVERAGE($H17:$L17) -> 0.47345994 | R17: =AVERAGE($H17:$L17) -> 0.47345994 | S17: =AVERAGE($H17:$L17) -> 0.47345994 | T17: =AVERAGE($H17:$L17) -> 0.47345994 | ... V17: =AVERAGE($H17:$L17) -> 0.47345994
D18: Inventory | F18: Days | H18: =-H$48/H$26*365 -> 147.05258 | I18: =-I$48/I$26*365 -> 137.19557 | J18: =-J$48/J$26*365 -> 125.57405 | K18: =-K$48/K$26*365 -> 124.95364 | L18: =-L$48/L$26*365 -> 161.19434 | M18: =AVERAGE($H18:$L18) -> 139.19404 | N18: =AVERAGE($H18:$L18) -> 139.19404 | O18: =AVERAGE($H18:$L18) -> 139.19404 | P18: =AVERAGE($H18:$L18) -> 139.19404 | Q18: =AVERAGE($H18:$L18) -> 139.19404 | R18: =AVERAGE($H18:$L18) -> 139.19404 | S18: =AVERAGE($H18:$L18) -> 139.19404 | T18: =AVERAGE($H18:$L18) -> 139.19404 | ... V18: =AVERAGE($H18:$L18) -> 139.19404
D19: Accounts Payable | F19: Days | H19: =-H$60/H$26*356 -> 2.8299814 | I19: =-I$60/I$26*356 -> 1.3273863 | J19: =-J$60/J$26*356 -> 2.4723954 | K19: =-K$60/K$26*356 -> 1.7944292 | L19: =-L$60/L$26*356 -> 2.6277842 | M19: =AVERAGE($H19:$L19) -> 2.2103953 | N19: =AVERAGE($H19:$L19) -> 2.2103953 | O19: =AVERAGE($H19:$L19) -> 2.2103953 | P19: =AVERAGE($H19:$L19) -> 2.2103953 | Q19: =AVERAGE($H19:$L19) -> 2.2103953 | R19: =AVERAGE($H19:$L19) -> 2.2103953 | S19: =AVERAGE($H19:$L19) -> 2.2103953 | T19: =AVERAGE($H19:$L19) -> 2.2103953 | ... V19: =AVERAGE($H19:$L19) -> 2.2103953
D20: Capital Asset Turnover Ratio | F20: Times | H20: =H$25/H$52 -> 22.432685 | I20: =I$25/I$52 -> 24.025855 | J20: =J$25/J$52 -> 25.897889 | K20: =K$25/K$52 -> 24.54795 | L20: =L$25/L$52 -> 23.176232 | M20: =L20+0.5 -> 23.676232 | N20: =M20+0.5 -> 24.176232 | O20: =N20+0.5 -> 24.676232 | P20: =O20+0.5 -> 25.176232 | Q20: =P20+0.5 -> 25.676232 | R20: =Q20+0.5 -> 26.176232 | S20: =R20+0.5 -> 26.676232 | T20: =S20+0.5 -> 27.176232 | ... V20: =U20+0.5 -> 28.176232
A23: Income Statement
B24: INCOME
D25: Revenue | F25: ₹ In lakh | H25: =Historical!H5 -> 181862 | I25: =Historical!I5 -> 219308 | J25: =Historical!J5 -> 315255 | K25: =Historical!K5 -> 382678 | L25: =Historical!L5 -> 491058 | M25: =Historical!S116 -> 767664.85 | N25: =M25*(1+N8) -> 848269.66 | O25: =N25*(1+O8) -> 924613.93 | P25: =O25*(1+P8) -> 998583.04 | Q25: =P25*(1+Q8) -> 1068483.9 | R25: =Q25*(1+R8) -> 1132592.9 | S25: =R25*(1+S8) -> 1194885.5 | T25: =S25*(1+T8) -> 1254629.8 | U25: =T25*(1+U8) -> 1311088.1 | V25: =U25*(1+V8) -> 1363531.6
D26: Cost of Goods Sold | F26: ₹ In lakh | H26: =-SUM(Historical!H9:H12) -> -161145.78 | I26: =-SUM(Historical!I9:I12) -> -199538 | J26: =-SUM(Historical!J9:J12) -> -285532 | K26: =-SUM(Historical!K9:K12) -> -347384 | L26: =-SUM(Historical!L9:L12) -> -448017 | M26: =-M$25*M$9 -> -694242.34 | N26: =-N$25*N$9 -> -767137.78 | O26: =-O$25*O$9 -> -836180.18 | P26: =-P$25*P$9 -> -903074.6 | Q26: =-Q$25*Q$9 -> -966289.82 | R26: =-R$25*R$9 -> -1024267.2 | S26: =-S$25*S$9 -> -1080601.9 | T26: =-T$25*T$9 -> -1134632 | ... V26: =-V$25*V$9 -> -1233118.1
D27: Gross Profit | F27: ₹ In lakh | H27: =SUM(H25:H26) -> 20716.22 | I27: =SUM(I25:I26) -> 19770 | J27: =SUM(J25:J26) -> 29723 | K27: =SUM(K25:K26) -> 35294 | L27: =SUM(L25:L26) -> 43041 | M27: =SUM(M$25:M$26) -> 73422.514 | N27: =SUM(N$25:N$26) -> 81131.878 | O27: =SUM(O$25:O$26) -> 88433.748 | P27: =SUM(P$25:P$26) -> 95508.447 | Q27: =SUM(Q$25:Q$26) -> 102194.04 | R27: =SUM(R$25:R$26) -> 108325.68 | S27: =SUM(S$25:S$26) -> 114283.59 | T27: =SUM(T$25:T$26) -> 119997.77 | ... V27: =SUM(V$25:V$26) -> 130413.58
C28: EXPENSES
D29: Salaries and Benefits | F29: ₹ In lakh | H29: =-Historical!H13 -> -3328.13 | I29: =-Historical!I13 -> -4513 | J29: =-Historical!J13 -> -5842 | K29: =-Historical!K13 -> -6818 | L29: =-Historical!L13 -> -9340 | M29: =-M$25*M$10 -> -14469.93 | N29: =-N$25*N$10 -> -15989.273 | O29: =-O$25*O$10 -> -17428.307 | P29: =-P$25*P$10 -> -18822.572 | Q29: =-Q$25*Q$10 -> -20140.152 | R29: =-R$25*R$10 -> -21348.561 | S29: =-S$25*S$10 -> -22522.732 | T29: =-T$25*T$10 -> -23648.868 | ... V29: =-V$25*V$10 -> -25701.59
D30: Other SG&A Expenses | F30: ₹ In lakh | H30: =-Historical!H16 -> -2685.74 | I30: =-Historical!I16 -> -6638 | J30: =-Historical!J16 -> -8591 | K30: =-Historical!K16 -> -7239 | L30: =-Historical!L16 -> -11805 | M30: =-M$25*M$11 -> -17693.68 | N30: =-N$25*N$11 -> -19551.516 | O30: =-O$25*O$11 -> -21311.152 | P30: =-P$25*P$11 -> -23016.044 | Q30: =-Q$25*Q$11 -> -24627.168 | R30: =-R$25*R$11 -> -26104.798 | S30: =-S$25*S$11 -> -27540.561 | T30: =-T$25*T$11 -> -28917.59 | ... V30: =-V$25*V$11 -> -31427.636
D31: EBITDA | F31: ₹ In lakh | H31: =SUM(H27:H30) -> 14702.35 | I31: =SUM(I27:I30) -> 8619 | J31: =SUM(J27:J30) -> 15290 | K31: =SUM(K27:K30) -> 21237 | L31: =SUM(L27:L30) -> 21896 | M31: =SUM(M27:M30) -> 41258.905 | N31: =SUM(N27:N30) -> 45591.09 | O31: =SUM(O27:O30) -> 49694.288 | ... V31: =SUM(V27:V30) -> 73284.353
D32: Depriciation & Amortization Expenses | F32: ₹ In lakh | H32: =-Historical!H15 -> -946.99 | I32: =-Historical!I15 -> -965 | J32: =-Historical!J15 -> -1339 | K32: =-Historical!K15 -> -1636 | L32: =-Historical!L15 -> -2369 | M32: =M$117 -> -2945.8267 | N32: =N$117 -> -3210.2213 | O32: =O$117 -> -3441.2262 | P32: =P$117 -> -4506.5533 | Q32: =Q$117 -> -4577.7509 | R32: =R$117 -> -4640.9357 | S32: =S$117 -> -4344.2137 | T32: =T$117 -> -4447.6707 | ... V32: =V$117 -> -5575.7021
D33: EBIT | F33: ₹ In lakh | H33: =SUM(H31:H32) -> 13755.36 | I33: =SUM(I31:I32) -> 7654 | J33: =SUM(J31:J32) -> 13951 | K33: =SUM(K31:K32) -> 19601 | L33: =SUM(L31:L32) -> 19527 | M33: =SUM(M31:M32) -> 38313.078 | N33: =SUM(N31:N32) -> 42380.869 | O33: =SUM(O31:O32) -> 46253.062 | ... V33: =SUM(V31:V32) -> 67708.651
D34: Interest | F34: ₹ In lakh | H34: =-Historical!H14 -> -2290.57 | I34: =-Historical!I14 -> -2618 | J34: =-Historical!J14 -> -3492 | K34: =-Historical!K14 -> -3633 | L34: =-Historical!L14 -> -4107 | M34: =M$124 -> -6155.6357 | N34: =N$124 -> -6155.6357 | O34: =O$124 -> -6155.6357 | P34: =P$124 -> -6155.6357 | Q34: =Q$124 -> -6155.6357 | R34: =R$124 -> -6155.6357 | S34: =S$124 -> -6155.6357 | T34: =T$124 -> -6155.6357 | ... V34: =V$124 -> -6155.6357
D35: Other Income (Expenses) | F35: ₹ In lakh | H35: =Historical!H6 -> 232.14 | I35: =Historical!I6 -> 167 | J35: =Historical!J6 -> 335 | K35: =Historical!K6 -> 541 | L35: =Historical!L6 -> 572 | M35: =M$25*M$14 -> 871.93422 | N35: =N$25*N$14 -> 963.48731 | O35: =O$25*O$14 -> 1050.2012 | P35: =P$25*P$14 -> 1134.2173 | Q35: =Q$25*Q$14 -> 1213.6125 | R35: =R$25*R$14 -> 1286.4292 | S35: =S$25*S$14 -> 1357.1828 | T35: =T$25*T$14 -> 1425.042 | ... V35: =V$25*V$14 -> 1548.7356
D36: Earnings before Tax | F36: ₹ In lakh | H36: =SUM(H33:H35) -> 11696.93 | I36: =SUM(I33:I35) -> 5203 | J36: =SUM(J33:J35) -> 10794 | K36: =SUM(K33:K35) -> 16509 | L36: =SUM(L33:L35) -> 15992 | M36: =SUM(M33:M35) -> 33029.377 | N36: =SUM(N33:N35) -> 37188.72 | O36: =SUM(O33:O35) -> 41147.627 | ... V36: =SUM(V33:V35) -> 63101.751
D37: Taxes | F37: ₹ In lakh | H37: =-Historical!H23 -> -3038.73 | I37: =-Historical!I23 -> -1348 | J37: =-Historical!J23 -> -2820 | K37: =-Historical!K23 -> -4184 | L37: =-Historical!L23 -> -4122 | M37: =-M36*M13 -> -2550.2265 | N37: =-N36*N13 -> -2871.373 | O37: =-O36*O13 -> -3177.0436 | P37: =-P36*P13 -> -3408.2309 | Q37: =-Q36*Q13 -> -3698.9364 | R37: =-R36*R13 -> -3965.718 | S37: =-S36*S13 -> -4252.5914 | T37: =-T36*T13 -> -4497.7681 | ... V37: =-V36*V13 -> -4872.1404
D38: Net Earnings | F38: ₹ In lakh | H38: =SUM(H36:H37) -> 8658.2 | I38: =SUM(I36:I37) -> 3855 | J38: =SUM(J36:J37) -> 7974 | K38: =SUM(K36:K37) -> 12325 | L38: =SUM(L36:L37) -> 11870 | M38: =SUM(M36:M37) -> 30479.15 | N38: =SUM(N36:N37) -> 34317.347 | O38: =SUM(O36:O37) -> 37970.584 | ... V38: =SUM(V36:V37) -> 58229.611
A41: Balance Sheet
B43: Assets
C44: Current Assets: | H44: =SUM(H45:H49) -> 68173.99 | I44: =SUM(I45:I49) -> 79855 | J44: =SUM(J45:J49) -> 110909 | K44: =SUM(K45:K49) -> 130625 | L44: =SUM(L45:L49) -> 231886 | M44: =SUM(M45:M49) -> 255879.31 | N44: =SUM(N45:N49) -> 282804.9 | O44: =SUM(O45:O49) -> 312910.03 | ... V44: =SUM(V45:V49) -> 601412.5
D45: Cash | F45: ₹ In lakh | H45: =Historical!H43 -> 1029.92 | I45: =Historical!I43 -> 365 | J45: =Historical!J43 -> 566 | K45: =Historical!K43 -> 1357 | L45: =Historical!L43 -> 8856 | M45: =M102 -> -34181.232 | N45: =N102 -> -35159.132 | O45: =O102 -> -31482.588 | P45: =P102 -> -23689.849 | Q45: =Q102 -> -11614.903 | R45: =R102 -> 5086.798 | S45: =S102 -> 24897.761 | T45: =T102 -> 48058.685 | ... V45: =V102 -> 105076.88
D46: Bank Deposits | F46: ₹ In lakh | H46: =Historical!H44 -> 662.63 | I46: =Historical!I44 -> 1294 | J46: =Historical!J44 -> 7073 | K46: =Historical!K44 -> 6822 | L46: =Historical!L44 -> 15323 | M46: =L46 -> 15323 | N46: =M46 -> 15323 | O46: =N46 -> 15323 | P46: =O46 -> 15323 | Q46: =P46 -> 15323 | R46: =Q46 -> 15323 | S46: =R46 -> 15323 | T46: =S46 -> 15323 | ... V46: =U46 -> 15323
...

Sheet Scenario
A1: THANGAMAYIL JEWELLERY LIMITED
A2: Scenarios
C4: Scenarios | E4: Growth(%) | H4: =Model!M2 -> 2026 | I4: =Model!N2 -> 2027 | J4: =Model!O2 -> 2028 | K4: =Model!P2 -> 2029 | L4: =Model!Q2 -> 2030 | M4: =Model!R2 -> 2031 | N4: =Model!S2 -> 2032 | O4: =Model!T2 -> 2033 | ... Q4: =Model!V2 -> 2035
D5: Base Case | E5: 0.2 | I5: 0.18 | J5: 0.15 | K5: 0.12 | L5: 0.09 | M5: 0.075 | N5: 0.06 | O5: 0.05 | P5: 0.045 | Q5: 0.04
D6: Bull Case | E6: 0.25 | I6: 0.21 | J6: 0.18 | K6: 0.145 | L6: 0.11 | M6: 0.09 | N6: 0.075 | O6: 0.06 | P6: 0.05 | Q6: 0.045
D7: Bear Case | E7: 0.12 | I7: 0.105 | J7: 0.09 | K7: 0.08 | L7: 0.07 | M7: 0.06 | N7: 0.055 | O7: 0.05 | P7: 0.045 | Q7: 0.04

Sheet Ratio Analysis
N6: INR Lakhs
B7: Ratio Analysis | T7: Interpretation of ratios
B8: Particulars | C8: =Model!H2 -> 2021 | D8: =Model!I2 -> 2022 | E8: =Model!J2 -> 2023 | F8: =Model!K2 -> 2024 | G8: =Model!L2 -> 2025 | H8: =Model!M2 -> 2026 | I8: =Model!N2 -> 2027 | J8: =Model!O2 -> 2028 | ... Q8: =Model!V2 -> 2035 | R8: Trend
C9: Audited | D9: Audited | E9: Audited | F9: Audited | G9: Audited | H9: Estimated | I9: Projected | J9: Projected | K9: Projected | L9: Projected | M9: Projected | N9: Projected | O9: Projected | P9: Projected | Q9: Projected
B10: Profitability Ratios
B11: Gross Margin | C11: =Model!H$27/Model!H$25 -> 0.11391176 | D11: =Model!I$27/Model!I$25 -> 0.09014719 | E11: =Model!J$27/Model!J$25 -> 0.094282406 | F11: =Model!K$27/Model!K$25 -> 0.092228976 | G11: =Model!L$27/Model!L$25 -> 0.087649524 | H11: =Model!M$27/Model!M$25 -> 0.095643971 | I11: =Model!N$27/Model!N$25 -> 0.095643971 | J11: =Model!O$27/Model!O$25 -> 0.095643971 | ... Q11: =Model!V$27/Model!V$25 -> 0.095643971 | T11: The Gross margin in the audited years is around 9.6% on an average and in the forecasted period the gross margin of 9.6% is almost equal to the audited years average margin rate. By this, we can interpret that Thangamayil Jewellery Limited is performing consistently in managing its production costs and Purchases related expenses. This indicates that TMJL has consistent growth potential in its business.
B12: EBITDA Margin | C12: =Model!H$31/Model!H$25 -> 0.080843442 | D12: =Model!I$31/Model!I$25 -> 0.039300892 | E12: =Model!J$31/Model!J$25 -> 0.04850042 | F12: =Model!K$31/Model!K$25 -> 0.055495743 | G12: =Model!L$31/Model!L$25 -> 0.044589438 | H12: =Model!M$31/Model!M$25 -> 0.053745987 | I12: =Model!N$31/Model!N$25 -> 0.053745987 | J12: =Model!O$31/Model!O$25 -> 0.053745987 | ... Q12: =Model!V$31/Model!V$25 -> 0.053745987 | T12: The forecasted EBITDA margin is 5.4% for all the forecasted years which is almost equal to the average of audited years of 5.4% as we have followed latest analysis method due to which the forecasted period thoughout will have same EBITDA margin rate. The consistent EBITDA margin signals that Thangamayil Jewellery Limited is performing as efficiently as the initial audited years. We can assume that TMJL follows the cost controlling techniques of the historical average consistently all along the future years.
B13: Operating Margin | C13: =Model!H$33/Model!H$25 -> 0.075636252 | D13: =Model!I$33/Model!I$25 -> 0.034900688 | E13: =Model!J$33/Model!J$25 -> 0.044253065 | F13: =Model!K$33/Model!K$25 -> 0.051220608 | G13: =Model!L$33/Model!L$25 -> 0.03976516 | H13: =Model!M$33/Model!M$25 -> 0.0499086 | I13: =Model!N$33/Model!N$25 -> 0.049961552 | J13: =Model!O$33/Model!O$25 -> 0.050024189 | ... Q13: =Model!V$33/Model!V$25 -> 0.049656825 | T13: There is a decrease in Operating margin rate in FY22 than FY21 by 4.1% and there onwards it fluctuates to 4.0% for remaining audited years. The Operating margin in the projected years is also increasing from 5.1% to 5.14% at a lower rate. Even though the EBITDA margin remains unchanged, Operating margin is increasing which is due to the effect of Depreciation & Amortisation. Because Capex is forecasted to increase slightly less than the Revenue growth rate.
B14: Pretax Margin | C14: =Model!H$36/Model!H$25 -> 0.064317614 | D14: =Model!I$36/Model!I$25 -> 0.023724625 | E14: =Model!J$36/Model!J$25 -> 0.034238949 | F14: =Model!K$36/Model!K$25 -> 0.043140708 | G14: =Model!L$36/Model!L$25 -> 0.032566418 | H14: =Model!M$36/Model!M$25 -> 0.043025777 | I14: =Model!N$36/Model!N$25 -> 0.043840682 | J14: =Model!O$36/Model!O$25 -> 0.044502496 | ... Q14: =Model!V$36/Model!V$25 -> 0.046278172 | T14: The year 2022 has faced market volatility due to which pre-tax margin has dropped by 4.0% from 6.4% and keeps on increasing from 2026 till the end of forecast period to 4.8%. Even though we have used latest analysis method for projections, there is an increase which is due to depreciation & amortisation, Finance costs which are projected as % on Fixed assets and borrowings, which are growing at lower rate than the revenue.
B15: Effective Tax rate | C15: =Model!H15 -> 0.25978868 | D15: =Model!I15 -> 0.2590813 | E15: =Model!J15 -> 0.26125625 | F15: =Model!K15 -> 0.25343752 | G15: =Model!L15 -> 0.25775388 | H15: =Model!M15 -> 0.25826353 | I15: =Model!N15 -> 0.25826353 | J15: =Model!O15 -> 0.26326353 | ... Q15: =Model!V15 -> 0.27826353 | T15: The effective tax rate for Thangamayil Jewellery Limited is assumed to be increased at 0.5% once for every two years, starting from its historical audited average of approximately 25.8%.
B16: Net Margin | C16: =Model!H38/Model!H25 -> 0.047608626 | D16: =Model!I38/Model!I25 -> 0.017578018 | E16: =Model!J38/Model!J25 -> 0.02529381 | F16: =Model!K38/Model!K25 -> 0.032207234 | G16: =Model!L38/Model!L25 -> 0.024172297 | H16: =Model!M38/Model!M25 -> 0.03970372 | I16: =Model!N38/Model!N25 -> 0.040455705 | J16: =Model!O38/Model!O25 -> 0.04106642 | ... Q16: =Model!V38/Model!V25 -> 0.042704994 | T16: As similar to pre-tax margin rate, Net margin has also faced drop by 3.0% in 2022 as a market volatility effect. But when we go through the forecasted period the net profit rate is increased form 4.1% to 4.5% only which is lower than the pre-tax margin growth. This slow growth rate is due to the effect of increase in tax rate by 0.5% once for every 2 years.
B18: DuPont/Earning Power
B19: Asset Turnover | D19: =Model!I$25/AVERAGE(Model!H$56:I$56) -> 2.6107382 | E19: =Model!J$25/AVERAGE(Model!I$56:J$56) -> 2.9303149 | F19: =Model!K$25/AVERAGE(Model!J$56:K$56) -> 2.8059069 | G19: =Model!L$25/AVERAGE(Model!K$56:L$56) -> 2.4307877 | H19: =Model!M$25/AVERAGE(Model!L$56:M$56) -> 2.8551579 | I19: =Model!N$25/AVERAGE(Model!M$56:N$56) -> 2.8647062 | J19: =Model!O$25/AVERAGE(Model!N$56:O$56) -> 2.8346384 | K19: =Model!P$25/AVERAGE(Model!O$56:P$56) -> 2.7825709 | ... Q19: =Model!V$25/AVERAGE(Model!U$56:V$56) -> 2.2397857 | T19: In the audited period (2021–2025), the asset turnover ratio of Thangamayil Jewellery Limited shows a declining trend from 216.50% to 182.45%, despite a temporary rise in 2023. In the forecast period, the ratio initially increases across all scenarios in 2026–2030, indicating stronger revenue growth relative to assets. In the bull case, it peaks around 294% in 2030 and remains the highest, showing the most efficient asset utilization. In the base case, it rises to around 280% and then gradually declines to ~231% by 2035. In the bear case, it increases initially but declines steadily to ~213% by 2035. The decline in the later years indicates that asset growth begins to outpace revenue growth, reducing asset utilization efficiency, while the bull case maintains relatively stronger efficiency compared to base and bear scenarios.
B20: Pre tax ROA | D20: =Model!I$36/AVERAGE(Model!H$56:I$56) -> 0.061938784 | E20: =Model!J$36/AVERAGE(Model!I$56:J$56) -> 0.1003309 | F20: =Model!K$36/AVERAGE(Model!J$56:K$56) -> 0.12104881 | G20: =Model!L$36/AVERAGE(Model!K$56:L$56) -> 0.079162047 | H20: =Model!M$36/AVERAGE(Model!L$56:M$56) -> 0.12284539 | I20: =Model!N$36/AVERAGE(Model!M$56:N$56) -> 0.12559067 | J20: =Model!O$36/AVERAGE(Model!N$56:O$56) -> 0.12614848 | K20: =Model!P$36/AVERAGE(Model!O$56:P$56) -> 0.12300214 | ... Q20: =Model!V$36/AVERAGE(Model!U$56:V$56) -> 0.10365319 | T20: In the audited period (2022–2025), the Pre-tax ROA of Thangamayil Jewellery Limited shows a fluctuating trend, declining sharply from 13.92% in 2022 to 4.84% in 2023, and then improving to 8.17% by 2025. In the base case, the ratio recovers to around 11–13% during 2027–2030, peaking at 13.17%, and then gradually declines to about 11.21% by 2035, indicating moderate improvement in profitability before stabilizing. In the bull case, the ratio improves more strongly, reaching about 14.00% in 2030, and remains relatively higher at around 12.13% by 2035, reflecting better profitability and more efficient utilization of assets. In the bear case, although the ratio recovers initially to around 11.5%, it gradually declines to nearly 10.06% by 2035, indicating weaker profitability due to slower earnings growth relative to asset expansion.
B21: Pre Tax ROE | D21: =Model!I$36/AVERAGE(Model!H$69:I$69) -> 0.16724913 | E21: =Model!J$36/AVERAGE(Model!I$69:J$69) -> 0.30275152 | F21: =Model!K$36/AVERAGE(Model!J$69:K$69) -> 0.37436648 | G21: =Model!L$36/AVERAGE(Model!K$69:L$69) -> 0.20046004 | H21: =Model!M$36/AVERAGE(Model!L$69:M$69) -> 0.2691138 | I21: =Model!N$36/AVERAGE(Model!M$69:N$69) -> 0.24907793 | J21: =Model!O$36/AVERAGE(Model!N$69:O$69) -> 0.2299401 | K21: =Model!P$36/AVERAGE(Model!O$69:P$69) -> 0.20898098 | ... Q21: =Model!V$36/AVERAGE(Model!U$69:V$69) -> 0.1374545 | T21: Pre-tax Return on Equity was decreased from 37.60% to 14.59% by the end of audited years, thereafter it became decreasing year on year and dropped to 14.37% by the year 2035 end of forecast period. The decrease is due to a lower growth rate of pre-tax profit than that of shareholder's equity. Even though it is in a decreasing trend, the pre-tax ROE in 2035 of 14.37% reflects a stabilized return on a significantly larger accumulated equity base compared to the initial audited years.
B22: Tax Complement | C22: =Model!H$38/Model!H$36 -> 0.74021132 | D22: =Model!I$38/Model!I$36 -> 0.7409187 | E22: =Model!J$38/Model!J$36 -> 0.73874375 | F22: =Model!K$38/Model!K$36 -> 0.74656248 | G22: =Model!L$38/Model!L$36 -> 0.74224612 | H22: =Model!M$38/Model!M$36 -> 0.92278914 | I22: =Model!N$38/Model!N$36 -> 0.92278914 | J22: =Model!O$38/Model!O$36 -> 0.92278914 | ... Q22: =Model!V$38/Model!V$36 -> 0.92278914
B23: ROE | D23: =Model!I$38/AVERAGE(Model!H$69:I$69) -> 0.12391801 | E23: =Model!J$38/AVERAGE(Model!I$69:J$69) -> 0.22365579 | F23: =Model!K$38/AVERAGE(Model!J$69:K$69) -> 0.27948796 | G23: =Model!L$38/AVERAGE(Model!K$69:L$69) -> 0.14879068 | H23: =Model!M$38/AVERAGE(Model!L$69:M$69) -> 0.24833529 | I23: =Model!N$38/AVERAGE(Model!M$69:N$69) -> 0.22984641 | J23: =Model!O$38/AVERAGE(Model!N$69:O$69) -> 0.21218622 | K23: =Model!P$38/AVERAGE(Model!O$69:P$69) -> 0.19284538 | ... Q23: =Model!V$38/AVERAGE(Model!U$69:V$69) -> 0.12684152 | T23: Similar to the pre-tax Return on Equity, Return on Equity has also decreased from 27.83% to 10.81% by the end of the audited years and is in a decreasing trend in the forecasted years, dropping to 13.26% by the year 2035 end of the forecast period. The reason is the same as of pre-tax ROE. But in this case, the additional downward change is due to the assumed increase in the tax rate by 0.5% once for every 2 years.
B24: Equity Retention | C24: =(Model!H$38-Model!H$96)/Model!H$38 -> 1.095074 | D24: =(Model!I$38-Model!I$96)/Model!I$38 -> 1.3203632 | E24: =(Model!J$38-Model!J$96)/Model!J$38 -> 1.18924 | F24: =(Model!K$38-Model!K$96)/Model!K$38 -> 1.1558621 | G24: =(Model!L$38-Model!L$96)/Model!L$38 -> 1.1386689 | H24: =(Model!M$38-Model!M$96)/Model!M$38 -> 1.1798416 | I24: =(Model!N$38-Model!N$96)/Model!N$38 -> 1.1798416 | J24: =(Model!O$38-Model!O$96)/Model!O$38 -> 1.1798416 | ... Q24: =(Model!V$38-Model!V$96)/Model!V$38 -> 1.1798416 | T24: The Equity Retention ratio has been increasing from 2022 to 2025 (from 1.32 to 1.14) and remains constant around 1.18 throughout the forecasted period till 2035. The increase in retention ratio is due to constant dividend payout which is not growing parallel with revenue. The high equity retention ratio can be assumed as Thangamayil Jewellery Limited has been retaining more profits and distributing less profits to its shareholders which can be assumed that company might have thought of business expansion.
B25: Reinvestment Rate | D25: =(Model!I$38-Model!I$96)/AVERAGE(Model!H$69:I$69) -> 0.16361677 | E25: =(Model!J$38-Model!J$96)/AVERAGE(Model!I$69:J$69) -> 0.26598042 | F25: =(Model!K$38-Model!K$96)/AVERAGE(Model!J$69:K$69) -> 0.32304954 | G25: =(Model!L$38-Model!L$96)/AVERAGE(Model!K$69:L$69) -> 0.16942333 | H25: =(Model!M$38-Model!M$96)/AVERAGE(Model!L$69:M$69) -> 0.29299632 | I25: =(Model!N$38-Model!N$96)/AVERAGE(Model!M$69:N$69) -> 0.27118237 | J25: =(Model!O$38-Model!O$96)/AVERAGE(Model!N$69:O$69) -> 0.25034614 | K25: =(Model!P$38-Model!P$96)/AVERAGE(Model!O$69:P$69) -> 0.22752701 | ... Q25: =(Model!V$38-Model!V$96)/AVERAGE(Model!U$69:V$69) -> 0.14965291 | T25: The Reinvestment Rate has been fluctuating in the audited years from 30.48% to 17.86% and went on fluctuating to 15.64% by the year 2035 end of the projected years. This indicates that Shareholders will be getting inconsistent returns year on year on reinvesting in the company. The reason behind this might be the decreasing return on equity in the forecasted period. Even though the rate is inconsistent, 15.64%% can be considered as a reasonable reinvestment rate.
B27: Liquidity Ratio
B28: Quick ratio | C28: =(SUM(Model!H$45:H$49)-Model!H$48)/(SUM(Model!H$60:H$61)) -> 0.1652737 | D28: =(SUM(Model!I$45:I$49)-Model!I$48)/(SUM(Model!I$60:I$61)) -> 0.30137242 | E28: =(SUM(Model!J$45:J$49)-Model!J$48)/(SUM(Model!J$60:J$61)) -> 0.44194561 | F28: =(SUM(Model!K$45:K$49)-Model!K$48)/(SUM(Model!K$60:K$61)) -> 0.25662281 | G28: =(SUM(Model!L$45:L$49)-Model!L$48)/(SUM(Model!L$60:L$61)) -> 0.51588794 | H28: =(SUM(Model!M$45:M$49)-Model!M$48)/(SUM(Model!M$60:M$61)) -> -0.13270349 | I28: =(SUM(Model!N$45:N$49)-Model!N$48)/(SUM(Model!N$60:N$61)) -> -0.14480979 | J28: =(SUM(Model!O$45:O$49)-Model!O$48)/(SUM(Model!O$60:O$61)) -> -0.088161996 | ... Q28: =(SUM(Model!V$45:V$49)-Model!V$48)/(SUM(Model!V$60:V$61)) -> 1.8704179 | T28: For Thangamayil Jewellery Limited, the quick ratio during the audited period (2021–2025) shows an overall improving but volatile trend, increasing from 0.17 in 2021 to 0.52 in 2025, although it fluctuates in between. Despite the improvement, the ratio remains below 1, indicating that the company’s liquid assets are insufficient to fully cover short-term liabilities. In the forecast period, the ratio turns negative between 2026 and 2031, reaching around -0.61 in 2029, which suggests significant pressure on short-term liquidity and heavy reliance on inventory turnover or external financing to meet current obligations. However, from 2032 onwards, the ratio gradually improves and rises above 1 by 2035 (1.50), indicating that the company is expected to strengthen its liquidity position and improve its ability to meet short-term liabilities using quick assets. Overall, the projections indicate short-term liquidity stress in the mid-forecast period followed by gradual improvement in the later years.
B29: Current ratio | C29: =(SUM(Model!H$45:H$49))/(SUM(Model!H$60:H$61)) -> 3.4658479 | D29: =(SUM(Model!I$45:I$49))/(SUM(Model!I$60:I$61)) -> 4.9590138 | E29: =(SUM(Model!J$45:J$49))/(SUM(Model!J$60:J$61)) -> 3.8671199 | F29: =(SUM(Model!K$45:K$49))/(SUM(Model!K$60:K$61)) -> 2.8645833 | G29: =(SUM(Model!L$45:L$49))/(SUM(Model!L$60:L$61)) -> 3.5154483 | H29: =(SUM(Model!M$45:M$49))/(SUM(Model!M$60:M$61)) -> 3.8271341 | I29: =(SUM(Model!N$45:N$49))/(SUM(Model!N$60:N$61)) -> 4.2021098 | J29: =(SUM(Model!O$45:O$49))/(SUM(Model!O$60:O$61)) -> 4.6207259 | ... Q29: =(SUM(Model!V$45:V$49))/(SUM(Model!V$60:V$61)) -> 8.5765844 | T29: For Thangamayil Jewellery Limited, the current ratio during the audited period (2021–2025) remains strong but fluctuating, moving from 3.47 in 2021 to 3.52 in 2025, with a peak of 4.96 in 2022 and a dip to 2.86 in 2024. The ratio consistently remains well above 1, indicating that the company maintains sufficient current assets to meet its short-term liabilities. In the forecast period (2026–2035), the ratio shows a steady increasing trend from 3.82 to 9.46. This suggests a significant buildup of current assets relative to current liabilities, indicating a strong liquidity position. However, such a very high current ratio may also indicate inefficient utilization of working capital, as excess current assets may remain idle instead of being deployed effectively to generate higher returns
B30: Cash Cycle (Days) | C30: =Model!H$18+Model!H$17-Model!H$19 -> 144.74127 | D30: =Model!I$18+Model!I$17-Model!I$19 -> 136.30424 | E30: =Model!J$18+Model!J$17-Model!J$19 -> 123.46868 | F30: =Model!K$18+Model!K$17-Model!K$19 -> 123.56553 | G30: =Model!L$18+Model!L$17-Model!L$19 -> 159.20579 | H30: =Model!M$18+Model!M$17-Model!M$19 -> 137.4571 | I30: =Model!N$18+Model!N$17-Model!N$19 -> 137.4571 | J30: =Model!O$18+Model!O$17-Model!O$19 -> 137.4571 | ... Q30: =Model!V$18+Model!V$17-Model!V$19 -> 137.4571 | T30: For Thangamayil Jewellery Limited, the cash conversion cycle during the audited period (2021–2025) shows an initial improvement followed by deterioration. The cycle declined from 144.74 days in 2021 to around 123.47 days in 2023, indicating improved efficiency in managing inventory, receivables, and payables. However, it increased significantly to 159.21 days in 2025, suggesting slower cash realization and higher working capital requirements. In the forecast period (2026–2035), the cash cycle is expected to stabilize at around 137.46 days, indicating relatively stable working capital management. However, a cycle of over 130 days still reflects a long operating cycle, which is typical in the jewellery retail industry due to high inventory holding periods.
B32: Leverage
B33: Asset/Equity | C33: =Model!H$56/Model!H$69 -> 2.6011592 | D33: =Model!I$56/Model!I$69 -> 2.7912542 | E33: =Model!J$56/Model!J$69 -> 3.2062553 | F33: =Model!K$56/Model!K$69 -> 3.0031631 | G33: =Model!L$56/Model!L$69 -> 2.3216038 | H33: =Model!M$56/Model!M$69 -> 2.0839406 | I33: =Model!N$56/Model!N$69 -> 1.8999091 | J33: =Model!O$56/Model!O$69 -> 1.7579868 | ... Q33: =Model!V$56/Model!V$69 -> 1.310274 | T33: For Thangamayil Jewellery Limited, the Asset/Equity ratio during the audited period (2021–2025) shows a rising trend initially from 2.60 in 2021 to 3.21 in 2023, indicating higher financial leverage. However, the ratio declines to 2.32 by 2025, suggesting a reduction in reliance on debt financing. In the forecast period (2026–2035), the ratio steadily declines from 2.08 to 1.27, indicating that the company is expected to reduce leverage and rely more on equity financing. This gradual decline reflects improving financial stability and lower financial risk, as a smaller proportion of assets is funded through liabilities.
B34: Debt/Equity | C34: =Model!H$63/Model!H$69 -> 0.94089803 | D34: =Model!I$63/Model!I$69 -> 1.2946619 | E34: =Model!J$63/Model!J$69 -> 1.468582 | F34: =Model!K$63/Model!K$69 -> 1.0785514 | G34: =Model!L$63/Model!L$69 -> 0.72322765 | H34: =Model!M$63/Model!M$69 -> 0.58953923 | I34: =Model!N$63/Model!N$69 -> 0.48797764 | J34: =Model!O$63/Model!O$69 -> 0.40985444 | ... Q34: =Model!V$63/Model!V$69 -> 0.16507835 | T34: For Thangamayil Jewellery Limited, the Debt/Equity ratio during the audited period (2021–2025) initially increases from 0.94 in 2021 to 1.47 in 2023, indicating a higher reliance on debt financing. However, the ratio declines to 0.72 by 2025, suggesting that the company has started reducing its dependence on debt. In the forecast period (2026–2035), the ratio continues to decline steadily from 0.59 to 0.14, indicating a progressive reduction in financial leverage. This trend suggests that the company is expected to rely more on equity and internal accruals for funding, thereby reducing financial risk and improving long-term financial stability.
B35: % LT Debt to Total Capital | C35: =Model!H$63/(Model!H$63+Model!H$69) -> 0.48477458 | D35: =Model!I$63/(Model!I$63+Model!I$69) -> 0.56420594 | E35: =Model!J$63/(Model!J$63+Model!J$69) -> 0.59490914 | F35: =Model!K$63/(Model!K$63+Model!K$69) -> 0.51889572 | G35: =Model!L$63/(Model!L$63+Model!L$69) -> 0.41969362 | H35: =Model!M$63/(Model!M$63+Model!M$69) -> 0.37088687 | I35: =Model!N$63/(Model!N$63+Model!N$69) -> 0.32794689 | J35: =Model!O$63/(Model!O$63+Model!O$69) -> 0.29070692 | ... Q35: =Model!V$63/(Model!V$63+Model!V$69) -> 0.14168863 | T35: For Thangamayil Jewellery Limited, the % Long-Term Debt to Total Capital during the audited period (2021–2025) initially increases from 48.48% in 2021 to 59.49% in 2023, indicating a higher reliance on long-term debt in the capital structure. However, the ratio declines to 41.97% by 2025, suggesting a gradual reduction in long-term leverage. In the forecast period (2026–2035), the ratio steadily declines from 36.99% to 12.30%, indicating that the company is expected to significantly reduce its dependence on long-term debt financing. This trend reflects a shift towards equity and internal funding, which may improve financial stability and lower long-term financial risk.
B37: Operating
B38: A/R Turnover | D38: =Model!I$25/AVERAGE(Model!H$47:I$47) -> 842.79538 | E38: =Model!J$25/AVERAGE(Model!I$47:J$47) -> 1088.9637 | F38: =Model!K$25/AVERAGE(Model!J$47:K$47) -> 1030.0888 | G38: =Model!L$25/AVERAGE(Model!K$47:L$47) -> 763.69829 | H38: =Model!M$25/AVERAGE(Model!L$47:M$47) -> 827.32452 | I38: =Model!N$25/AVERAGE(Model!M$47:N$47) -> 809.37502 | J38: =Model!O$25/AVERAGE(Model!N$47:O$47) -> 804.11808 | K38: =Model!P$25/AVERAGE(Model!O$47:P$47) -> 800.57134 | ... Q38: =Model!V$25/AVERAGE(Model!U$47:V$47) -> 786.03664 | T38: For Thangamayil Jewellery Limited, the Accounts Receivable (A/R) Turnover during the audited period (2022–2025) shows a fluctuating trend, increasing from 698.89 in 2022 to 848.60 in 2024, indicating faster collection of receivables. However, the ratio declines to 595.14 in 2025, suggesting relatively slower receivable collections in that year. In the forecast period (2026–2035), the ratio initially declines to 529.22 in 2026 but gradually increases to 755.80 by 2035. This improvement indicates that the company is expected to enhance its receivables management and collection efficiency over time, resulting in faster conversion of credit sales into cash. Overall, the higher turnover ratio reflects efficient credit management and quicker cash realization from customers.
B39: Avg. A/R Days | C39: =Model!H$17 -> 0.51867322 | D39: =Model!I$17 -> 0.4360534 | E39: =Model!J$17 -> 0.36702035 | F39: =Model!K$17 -> 0.40632072 | G39: =Model!L$17 -> 0.63923203 | H39: =Model!M$17 -> 0.47345994 | I39: =Model!N$17 -> 0.47345994 | J39: =Model!O$17 -> 0.47345994 | ... Q39: =Model!V$17 -> 0.47345994 | T39: For Thangamayil Jewellery Limited, the Average Accounts Receivable Days during the audited period (2021–2025) shows a generally low and stable trend, declining from 0.52 days in 2021 to 0.37 days in 2023, indicating very fast collection of receivables. However, it increases slightly to 0.64 days in 2025, suggesting marginally slower collection compared to earlier years. In the forecast period (2026–2035), the ratio stabilizes at around 0.47 days, indicating consistent receivables collection efficiency. Overall, the extremely low collection period suggests that the company collects payments almost immediately, reflecting strong cash-based sales and efficient receivables management.
B40: Inventory Turnover | D40: =-Model!I$26/AVERAGE(Model!H$48:I$48) -> 2.8520703 | E40: =-Model!J$26/AVERAGE(Model!I$48:J$48) -> 3.2964511 | F40: =-Model!K$26/AVERAGE(Model!J$48:K$48) -> 3.1993811 | G40: =-Model!L$26/AVERAGE(Model!K$48:L$48) -> 2.8285687 | H40: =-Model!M$26/AVERAGE(Model!L$48:M$48) -> 3.0014232 | I40: =-Model!N$26/AVERAGE(Model!M$48:N$48) -> 2.7530393 | J40: =-Model!O$26/AVERAGE(Model!N$48:O$48) -> 2.7351582 | K40: =-Model!P$26/AVERAGE(Model!O$48:P$48) -> 2.7230941 | ... Q40: =-Model!V$26/AVERAGE(Model!U$48:V$48) -> 2.6736552 | T40: For Thangamayil Jewellery Limited, the Inventory Turnover during the audited period (2022–2025) remains relatively stable with slight fluctuations, moving from 2.30 in 2022 to 2.63 in 2024, before declining to 2.19 in 2025. This indicates moderate efficiency in converting inventory into sales, although the decline in 2025 suggests relatively slower inventory movement. In the forecast period (2026–2035), the ratio initially decreases to 1.94 in 2026 but gradually improves to around 2.57 by 2035. This upward trend indicates improving inventory management and faster inventory turnover over time, suggesting that the company is expected to utilize its inventory more efficiently to generate sales.
B41: Avg. Inventory Days | C41: =Model!H$18 -> 147.05258 | D41: =Model!I$18 -> 137.19557 | E41: =Model!J$18 -> 125.57405 | F41: =Model!K$18 -> 124.95364 | G41: =Model!L$18 -> 161.19434 | H41: =Model!M$18 -> 139.19404 | I41: =Model!N$18 -> 139.19404 | J41: =Model!O$18 -> 139.19404 | ... Q41: =Model!V$18 -> 139.19404 | T41: For Thangamayil Jewellery Limited, the Average Inventory Days during the audited period (2021–2025) initially declines from 147.05 days in 2021 to 124.95 days in 2024, indicating improved efficiency in inventory management. However, the ratio increases significantly to 161.19 days in 2025, suggesting slower inventory movement and higher holding periods. In the forecast period (2026–2035), the ratio stabilizes at around 139.19 days, indicating consistent inventory holding levels. Although relatively high, such inventory days are common in the jewellery retail industry due to large inventory requirements and product variety, reflecting the nature of the business rather than inefficiency.
B42: A/P Turnover | D42: =-(Model!I$26)/AVERAGE(Model!H$60:I$60) -> 197.07359 | E42: =-(Model!J$26)/AVERAGE(Model!I$60:J$60) -> 209.41107 | F42: =-(Model!K$26)/AVERAGE(Model!J$60:K$60) -> 186.06535 | G42: =-(Model!L$26)/AVERAGE(Model!K$60:L$60) -> 177.15184 | H42: =-(Model!M$26)/AVERAGE(Model!L$60:M$60) -> 184.85409 | I42: =-(Model!N$26)/AVERAGE(Model!M$60:N$60) -> 173.36567 | J42: =-(Model!O$26)/AVERAGE(Model!N$60:O$60) -> 172.23965 | K42: =-(Model!P$26)/AVERAGE(Model!O$60:P$60) -> 171.47994 | ... Q42: =-(Model!V$26)/AVERAGE(Model!U$60:V$60) -> 168.36666 | T42: For Thangamayil Jewellery Limited, the Accounts Payable (A/P) Turnover during the audited period (2022–2025) shows a declining trend, decreasing from 159.16 in 2022 to 137.36 in 2025. This indicates that the company is taking relatively longer time to pay its suppliers compared to earlier years. In the forecast period (2026–2035), the ratio initially declines to 119.29 in 2026 but gradually increases to around 161.89 by 2035. The improvement in later years indicates that the company is expected to pay its suppliers more frequently, reflecting stronger liquidity and improved payment management. Overall, the increasing trend suggests better efficiency in managing payables and maintaining supplier relationships.
B43: Avg. A/P Days | C43: =Model!H$19 -> 2.8299814 | D43: =Model!I$19 -> 1.3273863 | E43: =Model!J$19 -> 2.4723954 | F43: =Model!K$19 -> 1.7944292 | G43: =Model!L$19 -> 2.6277842 | H43: =Model!M$19 -> 2.2103953 | I43: =Model!N$19 -> 2.2103953 | J43: =Model!O$19 -> 2.2103953 | ... Q43: =Model!V$19 -> 2.2103953 | T43: For Thangamayil Jewellery Limited, the Average Accounts Payable Days during the audited period (2021–2025) shows a fluctuating trend, decreasing from 2.83 days in 2021 to 1.33 days in 2022, then rising to 2.63 days in 2025. This indicates variability in the time the company takes to settle its obligations with suppliers. In the forecast period (2026–2035), the ratio stabilizes at around 2.21 days, indicating consistent payment practices toward suppliers. Overall, the relatively low payable days suggest that the company settles its supplier obligations quickly, which may support strong supplier relationships but also indicates limited reliance on supplier credit for working capital management.
B44: Fixed Asset Turnover | D44: =Model!I$25/AVERAGE(Model!H$52:I$52) -> 25.449129 | E44: =Model!J$25/AVERAGE(Model!I$52:J$52) -> 29.600019 | F44: =Model!K$25/AVERAGE(Model!J$52:K$52) -> 27.568475 | G44: =Model!L$25/AVERAGE(Model!K$52:L$52) -> 26.704625 | H44: =Model!M$25/AVERAGE(Model!L$52:M$52) -> 34.675033 | I44: =Model!N$25/AVERAGE(Model!M$52:N$52) -> 35.462144 | J44: =Model!O$25/AVERAGE(Model!N$52:O$52) -> 36.289799 | K44: =Model!P$25/AVERAGE(Model!O$52:P$52) -> 37.806409 | ... Q44: =Model!V$25/AVERAGE(Model!U$52:V$52) -> 47.357326 | T44: For Thangamayil Jewellery Limited, the Fixed Asset Turnover during the audited period (2022–2025) remains relatively stable, fluctuating between 20.59 and 22.71, indicating consistent efficiency in generating revenue from its fixed asset base. In the forecast period (2026–2035), the ratio increases significantly from 21.81 in 2026 to 41.33 by 2035. This upward trend indicates that the company is expected to generate higher revenue relative to its fixed assets, reflecting improved utilization and efficiency of fixed assets over time. The rising ratio suggests that revenue growth is projected to outpace the growth in fixed assets, leading to stronger operational efficiency.
B45: WC / Sales Growth | E45: =AVERAGE(Model!J$44-Model!J$59,Model!I$44-Model!I$59)/Model!I$25-AVERAGE(Model!I$44-Model!I$59,Model!H$44-Model!H$59)/Model!H$25 -> 0.024192888 | F45: =AVERAGE(Model!K$44-Model!K$59,Model!J$44-Model!J$59)/Model!J$25-AVERAGE(Model!J$44-Model!J$59,Model!I$44-Model!I$59)/Model!I$25 -> -0.067554077 | G45: =AVERAGE(Model!L$44-Model!L$59,Model!K$44-Model!K$59)/Model!K$25-AVERAGE(Model!K$44-Model!K$59,Model!J$44-Model!J$59)/Model!J$25 -> 0.062617525 | H45: =AVERAGE(Model!M$44-Model!M$59,Model!L$44-Model!L$59)/Model!L$25-AVERAGE(Model!L$44-Model!L$59,Model!K$44-Model!K$59)/Model!K$25 -> 0.033522146 | I45: =AVERAGE(Model!N$44-Model!N$59,Model!M$44-Model!M$59)/Model!M$25-AVERAGE(Model!M$44-Model!M$59,Model!L$44-Model!L$59)/Model!L$25 -> -0.09793034 | J45: =AVERAGE(Model!O$44-Model!O$59,Model!N$44-Model!N$59)/Model!N$25-AVERAGE(Model!N$44-Model!N$59,Model!M$44-Model!M$59)/Model!M$25 -> 0.0080729764 | K45: =AVERAGE(Model!P$44-Model!P$59,Model!O$44-Model!O$59)/Model!O$25-AVERAGE(Model!O$44-Model!O$59,Model!N$44-Model!N$59)/Model!N$25 -> 0.011474216 | L45: =AVERAGE(Model!Q$44-Model!Q$59,Model!P$44-Model!P$59)/Model!P$25-AVERAGE(Model!P$44-Model!P$59,Model!O$44-Model!O$59)/Model!O$25 -> 0.013526181 | ... Q45: =AVERAGE(Model!V$44-Model!V$59,Model!U$44-Model!U$59)/Model!U$25-AVERAGE(Model!U$44-Model!U$59,Model!T$44-Model!T$59)/Model!T$25 -> 0.020102479 | T45: For Thangamayil Jewellery Limited, the Working Capital to Sales Growth during the audited period (2023–2025) shows a fluctuating trend, moving from 2.42% in 2023 to -6.76% in 2024, and then increasing to 6.26% in 2025. This indicates variability in the relationship between working capital requirements and sales growth. In the forecast period (2026–2035), the ratio initially declines to -9.65% in 2027, suggesting that sales growth is expected to outpace the growth in working capital during that period. However, the ratio gradually improves and turns positive from 2029 onwards, reaching around 2.22% by 2035, indicating that working capital requirements are expected to grow in line with sales over the long term. Overall, the trend suggests short-term volatility in working capital efficiency followed by stabilization as the company’s sales and working capital growth become more aligned over time.
B46: ROIC | C46: =Model!H$38/SUM(Model!H$69,Model!H$63) -> 0.14973787 | D46: =Model!I$38/SUM(Model!I$69,Model!I$63) -> 0.051808249 | E46: =Model!J$38/SUM(Model!J$69,Model!J$63) -> 0.083083271 | F46: =Model!K$38/SUM(Model!K$69,Model!K$63) -> 0.12023217 | G46: =Model!L$38/SUM(Model!L$69,Model!L$63) -> 0.062486839 | H46: =Model!M$38/SUM(Model!M$69,Model!M$63) -> 0.14179137 | I46: =Model!N$38/SUM(Model!N$69,Model!N$63) -> 0.14116359 | J46: =Model!O$38/SUM(Model!O$69,Model!O$63) -> 0.13845483 | ... Q46: =Model!V$38/SUM(Model!V$69,Model!V$63) -> 0.10348666 | T46: For Thangamayil Jewellery Limited, the Return on Invested Capital (ROIC) during the audited period (2021–2025) shows a fluctuating trend, declining from 14.97% in 2021 to 5.18% in 2022, then recovering to 12.02% in 2024, before dropping again to 6.25% in 2025. This volatility indicates inconsistent efficiency in generating returns from invested capital. In the forecast period (2026–2035), the ratio improves initially, peaking at around 15.74% in 2028, indicating stronger returns generated from invested capital. However, the ratio gradually declines to about 11.48% by 2035, suggesting that while the company continues to generate healthy returns, the efficiency of capital utilization is expected to moderate over the long term.

Sheet Comps
A1: THANGAMAYIL JEWELLERY LIMITED
A2: Comps
